Workbook

Sheet Summary
B1: Kitchen Hydroponics — Bill of Materials (v1)
B2: Recirculating DWC base build. Prices are single-unit estimates in USD, as of Jul 2026 — verify before ordering.
B4: How to use
B5: Include column (yellow, on the BOM tab): 1 = counted in totals, 0 = excluded. Toggle it to match what you're actually buying.
B6: Budget-path pH/EC sensors are ON by default; the two Atlas precision rows are OFF. The Atlas parts REPLACE the DFRobot pH/EC parts — don't run both.
B8: COST SUMMARY — included items only
B9: Build phase | C9: Cost ($) | E9: Bought
B10: V1 — Compute, drivers, power | C10: =SUMIFS(BOM!$H$2:$H$53,BOM!$A$2:$A$53,"V1") -> 147 | E10: Amazon | F10: 400
B11: V1.5 — Sensing, dosing, aeration | C11: =SUMIFS(BOM!$H$2:$H$53,BOM!$A$2:$A$53,"V1.5") -> 237.4 | E11: DFR | F11: 110
B12: V2 — Environmental + lighting | C12: =SUMIFS(BOM!$H$2:$H$53,BOM!$A$2:$A$53,"V2") -> 44 | E12: Home Depot | F12: 140
B13: V3 — Wireless node (per unit) | C13: =SUMIFS(BOM!$H$2:$H$53,BOM!$A$2:$A$53,"V3") -> 0
B14: Mechanical & plumbing | C14: =SUMIFS(BOM!$H$2:$H$53,BOM!$A$2:$A$53,"Mech") -> 92
B15: Consumables (not plants) | C15: =SUMIFS(BOM!$H$2:$H$53,BOM!$A$2:$A$53,"Consum") -> 81
B16: Bench tools | C16: =SUMIFS(BOM!$H$2:$H$53,BOM!$A$2:$A$53,"Bench") -> 0
B17: TOTAL (included) | C17: =SUM(BOM!$H$2:$H$53) -> 601.4 | E17: Total | F17: =SUM(F10:F16) -> 650
B19: For the precision build: set the two Atlas rows to Include=1 and the DFRobot pH/EC rows to Include=0. Net delta is about +$296.
B20: Price basis: single-unit estimates from ST, DigiKey, DFRobot, Atlas Scientific, Amazon, and PowerGrow listings (Jul 2026). Treat as planning figures; check current price and shipping at order time.

Sheet BOM
A1: Phase | B1: Subsystem | C1: Item / spec | D1: Bought | E1: Qty | F1: Unit $ | G1: Include | H1: Line $ | I1: Vendor | J1: Link | K1: Notes
A2: V1 | B2: Compute | C2: STM32 Nucleo-F446RE dev board | D2: 1 | E2: 1 | F2: 25 | G2: 1 | H2: =E2*F2*G2 -> 25 | I2: ST eStore / DigiKey | J2: https://estore.st.com/en/nucleo-f446re-cpn.html | K2: Onboard ST-LINK, no separate programmer. ~$25 from ST/DigiKey, ~$42 from Amazon/eBay resellers.
A3: V1 | B3: Compute | C3: USB Mini-B cable (for ST-LINK) | E3: 1 | F3: 6 | G3: 1 | H3: =E3*F3*G3 -> 6 | I3: Amazon | K3: Skip if you already have one.
A4: V1 | B4: Compute | C4: Breadboards (half/full) | E4: 2 | F4: 6 | G4: 1 | H4: =E4*F4*G4 -> 12 | I4: Amazon
A5: V1 | B5: Compute | C5: Jumper wire assortment (M-M / M-F / F-F) | E5: 1 | F5: 7 | G5: 1 | H5: =E5*F5*G5 -> 7 | I5: Amazon
A6: V1 | B6: Compute | C6: Perfboard / protoboard pack | D6: 1 | E6: 1 | F6: 10 | G6: 1 | H6: =E6*F6*G6 -> 10 | I6: Amazon | K6: For semi-permanent build once the breadboard version works.
A7: V1 | B7: Compute | C7: Male header strips (2.54mm) | D7: 1 | E7: 1 | F7: 7 | G7: 1 | H7: =E7*F7*G7 -> 7 | I7: Amazon
A8: V1 | B8: Compute | C8: Screw terminal blocks (assortment) | D8: 1 | E8: 1 | F8: 9 | G8: 1 | H8: =E8*F8*G8 -> 9 | I8: Amazon
A9: V1 | B9: Driver | C9: IRLZ44N logic-level MOSFETs (10-pk) | D9: 1 | E9: 1 | F9: 9 | G9: 1 | H9: =E9*F9*G9 -> 9 | I9: Amazon | K9: Pump switching; logic-level gate drives from 3.3V.
A10: V1 | B10: Driver | C10: Small MOSFETs AO3400 / 2N7000 (asst) | D10: 1 | E10: 1 | F10: 8 | G10: 1 | H10: =E10*F10*G10 -> 8 | I10: Amazon | K10: Small loads.
A11: V1 | B11: Driver | C11: 1N4007 diodes (100-pk) | D11: 1 | E11: 1 | F11: 7 | G11: 1 | H11: =E11*F11*G11 -> 7 | I11: Amazon | K11: Flyback across every pump motor.
A12: V1 | B12: Driver | C12: Resistor kit (incl 4.7k, gate Rs) | D12: 1 | E12: 1 | F12: 10 | G12: 1 | H12: =E12*F12*G12 -> 10 | I12: Amazon | K12: 4.7k is the DS18B20 1-Wire pull-up.
A13: V1 | B13: Driver | C13: Capacitor assortment (decoupling + bulk) | D13: 1 | E13: 1 | F13: 12 | G13: 1 | H13: =E13*F13*G13 -> 12 | I13: Amazon
A14: V1 | B14: Power | C14: 12V DC PSU, 5A+ | D14: 1 | E14: 1 | F14: 16 | G14: 1 | H14: =E14*F14*G14 -> 16 | I14: Amazon | K14: Sized to run pumps + 12V LED together.
A15: V1 | B15: Power | C15: Buck converter LM2596 (3-pk) | D15: 1 | E15: 1 | F15: 9 | G15: 1 | H15: =E15*F15*G15 -> 9 | I15: Amazon | K15: 5V/3.3V logic rails. Skip if powering Nucleo over USB during dev.
A16: V1 | B16: Power | C16: Multi-channel MOSFET board (optional) | E16: 1 | F16: 12 | G16: 0 | H16: =E16*F16*G16 -> 0 | I16: Amazon | K16: Convenience alternative to discrete MOSFETs above. Pick one approach, not both.
A17: V1.5 | B17: Sensing (budget) | C17: DFRobot Gravity pH Kit V2 (SEN0161-V2) | D17: 1 | E17: 1 | F17: 39.5 | G17: 1 | H17: =E17*F17*G17 -> 39.5 | I17: DFRobot / DigiKey | J17: https://www.digikey.com/en/products/detail/dfrobot/SEN0161-V2/9608223 | K17: Probe + conditioning board + cal solutions.
A18: V1.5 | B18: Sensing (budget) | C18: DFRobot Gravity EC sensor K=1 (DFR0300) | D18: 1 | E18: 1 | F18: 69.9 | G18: 1 | H18: =E18*F18*G18 -> 69.9 | I18: DFRobot | J18: https://www.dfrobot.com/topic-282.html | K18: EC tracks nutrient strength more directly than TDS; prefer over SEN0244.
A19: V1.5 | B19: Sensing (budget) | C19: Waterproof DS18B20 solution-temp probe | D19: 1 | E19: 1 | F19: 9 | G19: 1 | H19: =E19*F19*G19 -> 9 | I19: Amazon / DigiKey | K19: Required for temp compensation on pH and EC. Not optional.
A20: V1.5 | B20: Sensing (budget) | C20: Reservoir float switch (level) | D20: 1 | E20: 1 | F20: 8 | G20: 1 | H20: =E20*F20*G20 -> 8 | I20: Amazon | K20: Basic low/refill detection.
A21: V1.5 | B21: Sensing (budget) | C21: Ultrasonic level JSN-SR04T (optional) | E21: 1 | F21: 11 | G21: 0 | H21: =E21*F21*G21 -> 0 | I21: Amazon | K21: Continuous level for volume-based dosing math. Alternative to float switch.
A22: V1.5 | B22: Sensing (precision) | C22: Atlas Scientific EZO-pH Kit | E22: 1 | F22: 175 | G22: 0 | H22: =E22*F22*G22 -> 0 | I22: Atlas Scientific | J22: https://atlas-scientific.com/kits/ph-kit/ | K22: Isolated, I2C. REPLACES the DFRobot pH row. Verify current price (~$175).
A23: V1.5 | B23: Sensing (precision) | C23: Atlas Scientific EZO-EC Kit K1.0 (EC-KIT-1.0) | E23: 1 | F23: 229.99 | G23: 0 | H23: =E23*F23*G23 -> 0 | I23: Atlas Scientific | J23: https://atlas-scientific.com/kits/conductivity-k-1-0-kit/ | K23: Isolated, I2C. REPLACES the DFRobot EC row. Also solves probe cross-interference.
A24: V1.5 | B24: Dosing | C24: 12V peristaltic dosing pump (Kamoer NKP / INTLLAB) | D24: 1 | E24: 4 | F24: 18 | G24: 1 | H24: =E24*F24*G24 -> 72 | I24: Amazon | J24: https://www.amazon.com/Kamoer-Peristaltic-Hydroponics-Nutrient-Analytical/dp/B07GWJ78FN | K24: Nutrient A, Nutrient B, pH Down, pH Up. Start with 3 and defer pH Up if budget-limited.
A25: V1.5 | B25: Dosing | C25: Silicone dosing tubing 2x4mm (roll) | D25: 1 | E25: 1 | F25: 9 | G25: 1 | H25: =E25*F25*G25 -> 9 | I25: Amazon
A26: V1.5 | B26: Dosing | C26: Inline check valves (dosing lines) | D26: 1 | E26: 4 | F26: 2.5 | G26: 1 | H26: =E26*F26*G26 -> 10 | I26: Amazon | K26: Stop siphon-back into the stock bottles.
A27: V1.5 | B27: Aeration | C27: Air pump | D27: 1 | E27: 1 | F27: 12 | G27: 1 | H27: =E27*F27*G27 -> 12 | I27: Amazon | K27: DWC aeration.
A28: V1.5 | B28: Aeration | C28: Air stone(s) + airline tubing | E28: 1 | F28: 8 | G28: 1 | H28: =E28*F28*G28 -> 8 | I28: Amazon
A29: V1.5 | B29: Dosing | C29: Submersible pump (optional) | E29: 1 | F29: 12 | G29: 0 | H29: =E29*F29*G29 -> 0 | I29: Amazon | K29: Only if you add recirculation or switch to NFT.
A30: V2 | B30: Env sensing | C30: SHT31 temp/humidity breakout | E30: 1 | F30: 14 | G30: 1 | H30: =E30*F30*G30 -> 14 | I30: Adafruit / Amazon | K30: Better RH accuracy than BME280. Pick BME280 only if you want barometric pressure.
A31: V2 | B31: Env sensing | C31: BH1750 ambient light (lux) sensor | E31: 1 | F31: 5 | G31: 1 | H31: =E31*F31*G31 -> 5 | I31: Amazon | K31: Cheap grow-light feedback proxy.
A32: V2 | B32: Env sensing | C32: PAR / quantum sensor, Apogee (optional) | E32: 1 | F32: 220 | G32: 0 | H32: =E32*F32*G32 -> 0 | I32: Apogee | K32: Accurate umol data; only worth it if you need PAR. Expensive.
A33: V2 | B33: Lighting | C33: 12V full-spectrum LED grow strip / small panel | E33: 1 | F33: 25 | G33: 1 | H33: =E33*F33*G33 -> 25 | I33: Amazon | K33: Drive via MOSFET PWM for photoperiod and dimming.
A34: V2 | B34: Lighting | C34: Aluminum LED channel + heatsinking (optional) | E34: 1 | F34: 12 | G34: 0 | H34: =E34*F34*G34 -> 0 | I34: Amazon | K34: If you go with a higher-power strip.
A35: V3 | B35: Wireless | C35: STM32 Nucleo-WB55RG board (per node) | E35: 1 | F35: 50 | G35: 0 | H35: =E35*F35*G35 -> 0 | I35: ST / DigiKey | J35: https://www.digikey.com/en/products/detail/stmicroelectronics/NUCLEO-WB55RG/13684823 | K35: BLE on your CubeIDE toolchain (no ESP32 stack). P-NUCLEO-WB55 pack w/ USB dongle ~$77.
A36: Mech | B36: Reservoir | C36: Opaque food-grade reservoir (5-gal bucket / tote) | D36: 1 | E36: 1 | F36: 12 | G36: 1 | H36: =E36*F36*G36 -> 12 | I36: Hardware store | K36: Opaque prevents algae; a clear tank grows it.
A37: Mech | B37: Reservoir | C37: Lid + net pots + neoprene collars | E37: 1 | F37: 14 | G37: 1 | H37: =E37*F37*G37 -> 14 | I37: Amazon
A38: Mech | B38: Media | C38: Clay pebbles (hydroton) | E38: 1 | F38: 16 | G38: 1 | H38: =E38*F38*G38 -> 16 | I38: Amazon | K38: Growing medium, not a plant.
A39: Mech | B39: Media | C39: Rockwool starter cubes | E39: 1 | F39: 10 | G39: 1 | H39: =E39*F39*G39 -> 10 | I39: Amazon | K39: Seed-start medium, not a plant.
A40: Mech | B40: Plumbing | C40: Stock bottles for nutrient / pH solutions | D40: 1 | E40: 4 | F40: 3 | G40: 1 | H40: =E40*F40*G40 -> 12 | I40: Amazon | K40: Dosing pumps draw from these.
...
